<?xml version="1.0"?>
<robot name="sam_bot">

  <!-- Define robot constants -->
  <!-- base_radius = 0.5 -->
  <!-- base_height = 0.2 -->
  <!-- wheel_radius = 0.1 -->
  <!-- wheel_width = 0.04 -->
  <!-- wheel_zoff = 0.05 -->
  <!-- caster_radius =  0.05 -->
  <!-- base_m = 2 -->
  <!-- wheel_m = 0.4 -->
  <!-- caster_m = 1 -->
  
  <!-- Define robot color -->
  <material name="grey">
    <color rgba="0.5 0.5 0.5 1"/>
  </material>

  <material name="white">
    <color rgba="1 1 1 1"/>
  </material>  

  <material name="black">
    <color rgba="0 0 0 1"/>
  </material>  

  <!-- Robot Base -->
  <link name="base_link">
    <visual>
      <geometry>
        <!-- <box size="${base_length} ${base_width} ${base_height}"/> -->
        <cylinder radius="0.5" length="0.2"/>
      </geometry>
      <material name="white"/>
    </visual>

    <collision>
      <geometry>
        <cylinder radius="0.5" length="0.2"/>
      </geometry>
    </collision>

    <inertial>
      <mass value="2"/>
      <inertia ixx="0.13" ixy="0.0" ixz="0.0" iyy="0.13" iyz="0.0" izz="0.25"/>
    </inertial>
  </link>
  
  <!-- Robot Footprint -->
  <link name="base_footprint"/>

  <joint name="base_joint" type="fixed">
    <parent link="base_link"/>
    <child link="base_footprint"/>
    <origin xyz="0.0 0.0 -0.15" rpy="0 0 0"/>
  </joint>
  
  <!-- Wheels -->
  <link name="drivewhl_l_link">
    <visual>
      <origin xyz="0 0 0" rpy="1.57 0 0"/>
      <geometry>
          <cylinder radius="0.1" length="0.04"/>
      </geometry>
      <material name="black"/>
    </visual>

   <collision>
     <origin xyz="0 0 0" rpy="1.57 0 0"/>
     <geometry>
       <cylinder radius="0.1" length="0.04"/>
     </geometry>
   </collision>

   <inertial>
     <mass value="0.4"/>
     <inertia ixx="0.001" ixy="0.0" ixz="0.0" iyy="0.001" iyz="0.0" izz="0.002"/>
   </inertial>
  </link>

  <joint name="drivewhl_l_joint" type="continuous">
    <parent link="base_link"/>
    <child link="drivewhl_l_link"/>
    <origin xyz="0 0.5 -0.05" rpy="0 0 0"/>
    <axis xyz="0 1 0"/>
  </joint>

  <link name="drivewhl_r_link">
    <visual>
      <origin xyz="0 0 0" rpy="1.57 0 0"/>
      <geometry>
          <cylinder radius="0.1" length="0.04"/>
      </geometry>
      <material name="black"/>
    </visual>

   <collision>
     <origin xyz="0 0 0" rpy="1.57 0 0"/>
     <geometry>
       <cylinder radius="0.1" length="0.04"/>
     </geometry>
   </collision>

   <inertial>
     <mass value="0.4"/>
     <inertia ixx="0.001" ixy="0.0" ixz="0.0" iyy="0.001" iyz="0.0" izz="0.002"/>
   </inertial>
  </link>

  <joint name="drivewhl_r_joint" type="continuous">
    <parent link="base_link"/>
    <child link="drivewhl_r_link"/>
    <origin xyz="0 -0.5 -0.05" rpy="0 0 0"/>
    <axis xyz="0 1 0"/>
  </joint>

  
  <!-- Caster Wheel -->
  <link name="front_caster">
    <visual>
      <geometry>
        <sphere radius="0.05"/>
      </geometry>
      <material name="grey"/>
    </visual>

    <collision>
      <geometry>
        <sphere radius="0.05"/>
      </geometry>
    </collision>
    
    <inertial>
      <mass value="1"/>
      <inertia ixx="0.002" ixy="0.0" ixz="0.0" iyy="0.002" iyz="0.0" izz="0.002"/>
    </inertial>
  </link>

  <joint name="caster_joint" type="fixed">
    <parent link="base_link"/>
    <child link="front_caster"/>
    <origin xyz="0.4 0.0 -0.1" rpy="0 0 0"/>
  </joint>
</robot>
